Workbook

Sheet README
A1: TotalEnergies Marketing Kenya Plc (TOTL): Share Price Forecasting Model, Jan-Dec 2027
A3: Data source | B3: Historical monthly data (Jan 2023 - Oct 2026) supplied by the user from Rock Data Plus / Rock Investment Bank repository. Not independently verified against NSE, CBK or KNBS.
A4: Sheets | B4: Data: inputs + returns | Summary Stats: historical findings | Regression: LINEST model | Scenarios: 2027 assumptions and calculations | Forecast Table: results only | Cross-check: price-only methods | Chart | Qualitative Factors
A5: Colour code | B5: Blue text = hard-coded input or assumption (change these). Black = formula. Green = link from another sheet. Yellow fill = key assumptions you may edit.
A6: Method | B6: (1) Monthly return = % change in price. (2) OLS regression of return on change in interest rate (pp) and % change in KES/USD, estimated with LINEST on Jun 2023 - Oct 2026 (n=41). (3) For each 2027 scenario, predicted return = drift + b1 x change in rate + b2 x % change in FX. (4) Price(t) = Price(t-1) x (1 + return). Start price = Oct 2026 actual.
A7: What is estimated vs assumed | B7: ESTIMATED from data: regression coefficients, standard errors, R-squared, p-values. ASSUMED by the analyst: the 2027 interest-rate and exchange-rate paths, and the drift choice in each scenario (base = 50% of intercept, optimistic = 100%, pessimistic = lower 95% bound). These are not official forecasts.
A8: Reliability | B8: The regression is NOT statistically significant (R-squared about 1.8%, F-test p about 0.70). Results are scenarios, not predictions, and do not show that interest rates or exchange rates cause price changes.
A9: Gap months | B9: Nov-Dec 2026 are not modelled. The 2027 path starts from the Oct 2026 price, rate and exchange rate (Oct 2026 may be provisional).
A10: Cross-check sheet | B10: Naive, random-walk-with-drift and linear-trend columns are live formulas. Damped Holt and ARIMA(1,1,0) values were computed in Python (statsmodels) and are pasted as blue hard-codes.

Sheet Data
A1: Month | B1: Price (KES) | C1: Inflation (%) | D1: Exchange rate (KES/USD) | E1: Interest rate | F1: Monthly return (%) | G1: Change in rate (pp) | H1: Change in KES/USD (%) | I1: Log return | J1: t index (last 24m) | L1: Note: Data are as supplied (Rock Data Plus). Exchange-rate data begin May 2023, so the regression uses rows 7-47 (Jun 2023 - Oct 2026). Interest rate stored as a fraction (0.0875 = 8.75%).
A2: 44927 | B2: 23.23 | C2: 10.416 | E2: 0.0875
A3: 44958 | B3: 22.47 | C3: 10.6175 | E3: 0.0875 | F3: =(B3/B2-1)*100 -> -3.2716315 | G3: =(E3-E2)*100 -> 0 | H3: =IF(AND(ISNUMBER(D3),ISNUMBER(D2)),(D3/D2-1)*100,"") | I3: =LN(B3/B2) -> -0.033263461
A4: 44986 | B4: 20.63 | C4: 10.75 | E4: 0.0875 | F4: =(B4/B3-1)*100 -> -8.188696 | G4: =(E4-E3)*100 -> 0 | H4: =IF(AND(ISNUMBER(D4),ISNUMBER(D3)),(D4/D3-1)*100,"") | I4: =LN(B4/B3) -> -0.085434759
A5: 45017 | B5: 21.19 | C5: 10.9125 | E5: 0.095 | F5: =(B5/B4-1)*100 -> 2.7144935 | G5: =(E5-E4)*100 -> 0.75 | H5: =IF(AND(ISNUMBER(D5),ISNUMBER(D4)),(D5/D4-1)*100,"") | I5: =LN(B5/B4) -> 0.026783045
A6: 45047 | B6: 20.84 | C6: 11.282 | D6: 138.3971 | E6: 0.095 | F6: =(B6/B5-1)*100 -> -1.6517225 | G6: =(E6-E5)*100 -> 0 | H6: =IF(AND(ISNUMBER(D6),ISNUMBER(D5)),(D6/D5-1)*100,"") | I6: =LN(B6/B5) -> -0.016655155
A7: 45078 | B7: 20.65 | C7: 11.6925 | D7: 139.7493 | E7: 0.095 | F7: =(B7/B6-1)*100 -> -0.91170825 | G7: =(E7-E6)*100 -> 0 | H7: =IF(AND(ISNUMBER(D7),ISNUMBER(D6)),(D7/D6-1)*100,"") -> 0.97704359 | I7: =LN(B7/B6) -> -0.0091588975
A8: 45108 | B8: 19.42 | C8: 12.464 | D8: 141.5124 | E8: 0.105 | F8: =(B8/B7-1)*100 -> -5.9564165 | G8: =(E8-E7)*100 -> 1 | H8: =IF(AND(ISNUMBER(D8),ISNUMBER(D7)),(D8/D7-1)*100,"") -> 1.2616163 | I8: =LN(B8/B7) -> -0.061411857
A9: 45139 | B9: 19.48 | C9: 13.5525 | D9: 144.0414 | E9: 0.105 | F9: =(B9/B8-1)*100 -> 0.30895984 | G9: =(E9-E8)*100 -> 0 | H9: =IF(AND(ISNUMBER(D9),ISNUMBER(D8)),(D9/D8-1)*100,"") -> 1.7871225 | I9: =LN(B9/B8) -> 0.0030848354
A10: 45170 | B10: 18.33 | C10: 14.6425 | D10: 146.8216 | E10: 0.105 | F10: =(B10/B9-1)*100 -> -5.9034908 | G10: =(E10-E9)*100 -> 0 | H10: =IF(AND(ISNUMBER(D10),ISNUMBER(D9)),(D10/D9-1)*100,"") -> 1.9301395 | I10: =LN(B10/B9) -> -0.060849236
A11: 45200 | B11: 17.4 | C11: 15.262 | D11: 149.4429 | E11: 0.105 | F11: =(B11/B10-1)*100 -> -5.0736498 | G11: =(E11-E10)*100 -> 0 | H11: =IF(AND(ISNUMBER(D11),ISNUMBER(D10)),(D11/D10-1)*100,"") -> 1.785364 | I11: =LN(B11/B10) -> -0.052068856
A12: 45231 | B12: 16.37 | C12: 15.57 | D12: 152.1154 | E12: 0.105 | F12: =(B12/B11-1)*100 -> -5.9195402 | G12: =(E12-E11)*100 -> 0 | H12: =IF(AND(ISNUMBER(D12),ISNUMBER(D11)),(D12/D11-1)*100,"") -> 1.7883084 | I12: =LN(B12/B11) -> -0.061019815
A13: 45261 | B13: 16.82 | C13: 15.8125 | D13: 154.1563 | E13: 0.125 | F13: =(B13/B12-1)*100 -> 2.748931 | G13: =(E13-E12)*100 -> 2 | H13: =IF(AND(ISNUMBER(D13),ISNUMBER(D12)),(D13/D12-1)*100,"") -> 1.3416788 | I13: =LN(B13/B12) -> 0.027118263
A14: 45292 | B14: 17.55 | C14: 16.356 | D14: 159.7283 | E14: 0.125 | F14: =(B14/B13-1)*100 -> 4.3400713 | G14: =(E14-E13)*100 -> 0 | H14: =IF(AND(ISNUMBER(D14),ISNUMBER(D13)),(D14/D13-1)*100,"") -> 3.6145133 | I14: =LN(B14/B13) -> 0.042485295
A15: 45323 | B15: 17.35 | C15: 16.845 | D15: 151.2907 | E15: 0.13 | F15: =(B15/B14-1)*100 -> -1.1396011 | G15: =(E15-E14)*100 -> 0.5 | H15: =IF(AND(ISNUMBER(D15),ISNUMBER(D14)),(D15/D14-1)*100,"") -> -5.2824703 | I15: =LN(B15/B14) -> -0.011461444
A16: 45352 | B16: 17.76 | C16: 16.9825 | D16: 137.0702 | E16: 0.13 | F16: =(B16/B15-1)*100 -> 2.3631124 | G16: =(E16-E15)*100 -> 0 | H16: =IF(AND(ISNUMBER(D16),ISNUMBER(D15)),(D16/D15-1)*100,"") -> -9.3994542 | I16: =LN(B16/B15) -> 0.023356231
A17: 45383 | B17: 18.91 | C17: 16.702 | D17: 131.5728 | E17: 0.13 | F17: =(B17/B16-1)*100 -> 6.4752252 | G17: =(E17-E16)*100 -> 0 | H17: =IF(AND(ISNUMBER(D17),ISNUMBER(D16)),(D17/D16-1)*100,"") -> -4.0106456 | I17: =LN(B17/B16) -> 0.062742145
... A23: 45566 | B23: 20.84 | C23: 16.11 | D23: 129.1962 | E23: 0.12 | F23: =(B23/B22-1)*100 -> 2.8627838 | G23: =(E23-E22)*100 -> -0.75 | H23: =IF(AND(ISNUMBER(D23),ISNUMBER(D22)),(D23/D22-1)*100,"") -> -0.0044116998 | I23: =LN(B23/B22) -> 0.028225718
A24: 45597 | B24: 20.6 | C24: 14.1525 | D24: 129.4075 | E24: 0.12 | F24: =(B24/B23-1)*100 -> -1.1516315 | G24: =(E24-E23)*100 -> 0 | H24: =IF(AND(ISNUMBER(D24),ISNUMBER(D23)),(D24/D23-1)*100,"") -> 0.1635497 | I24: =LN(B24/B23) -> -0.011583141 | J24: 1
A25: 45627 | B25: 20.36 | C25: 11.834 | D25: 129.3459 | E25: 0.1125 | F25: =(B25/B24-1)*100 -> -1.1650485 | G25: =(E25-E24)*100 -> -0.75 | H25: =IF(AND(ISNUMBER(D25),ISNUMBER(D24)),(D25/D24-1)*100,"") -> -0.047601569 | I25: =LN(B25/B24) -> -0.011718884 | J25: 2
A26: 45658 | B26: 21.37 | C26: 11.3225 | D26: 129.3862 | E26: 0.1125 | F26: =(B26/B25-1)*100 -> 4.9607073 | G26: =(E26-E25)*100 -> 0 | H26: =IF(AND(ISNUMBER(D26),ISNUMBER(D25)),(D26/D25-1)*100,"") -> 0.031156766 | I26: =LN(B26/B25) -> 0.048415878 | J26: 3
A27: 45689 | B27: 22.78 | C27: 10.7975 | D27: 129.3043 | E27: 0.1075 | F27: =(B27/B26-1)*100 -> 6.5980346 | G27: =(E27-E26)*100 -> -0.5 | H27: =IF(AND(ISNUMBER(D27),ISNUMBER(D26)),(D27/D26-1)*100,"") -> -0.063298868 | I27: =LN(B27/B26) -> 0.063894889 | J27: 4
A28: 45717 | B28: 22.99 | C28: 10.468 | D28: 129.3367 | E28: 0.1075 | F28: =(B28/B27-1)*100 -> 0.92186128 | G28: =(E28-E27)*100 -> 0 | H28: =IF(AND(ISNUMBER(D28),ISNUMBER(D27)),(D28/D27-1)*100,"") -> 0.025057171 | I28: =LN(B28/B27) -> 0.0091763808 | J28: 5
A29: 45748 | B29: 22.21 | C29: 10.1775 | D29: 129.5189 | E29: 0.1 | F29: =(B29/B28-1)*100 -> -3.3927795 | G29: =(E29-E28)*100 -> -0.75 | H29: =IF(AND(ISNUMBER(D29),ISNUMBER(D28)),(D29/D28-1)*100,"") -> 0.14087262 | I29: =LN(B29/B28) -> -0.034516701 | J29: 6
A30: 45778 | B30: 22.69 | C30: 10.005 | D30: 129.2767 | E30: 0.1 | F30: =(B30/B29-1)*100 -> 2.1611887 | G30: =(E30-E29)*100 -> 0 | H30: =IF(AND(ISNUMBER(D30),ISNUMBER(D29)),(D30/D29-1)*100,"") -> -0.18699974 | I30: =LN(B30/B29) -> 0.021381661 | J30: 7
A31: 45809 | B31: 24.16 | C31: 9.842 | D31: 129.2453 | E31: 0.0975 | F31: =(B31/B30-1)*100 -> 6.4786249 | G31: =(E31-E30)*100 -> -0.25 | H31: =IF(AND(ISNUMBER(D31),ISNUMBER(D30)),(D31/D30-1)*100,"") -> -0.024288986 | I31: =LN(B31/B30) -> 0.062774074 | J31: 8
A32: 45839 | B32: 24.19 | C32: 9.72 | D32: 129.2444 | E32: 0.0975 | F32: =(B32/B31-1)*100 -> 0.12417219 | G32: =(E32-E31)*100 -> 0 | H32: =IF(AND(ISNUMBER(D32),ISNUMBER(D31)),(D32/D31-1)*100,"") -> -0.00069635027 | I32: =LN(B32/B31) -> 0.0012409516 | J32: 9
A33: 45870 | B33: 29.56 | C33: 9.27 | D33: 129.2432 | E33: 0.095 | F33: =(B33/B32-1)*100 -> 22.199256 | G33: =(E33-E32)*100 -> -0.25 | H33: =IF(AND(ISNUMBER(D33),ISNUMBER(D32)),(D33/D32-1)*100,"") -> -0.0009284735 | I33: =LN(B33/B32) -> 0.20048277 | J33: 10
A34: 45901 | B34: 35.51 | C34: 9.554 | D34: 129.2426 | E34: 0.095 | F34: =(B34/B33-1)*100 -> 20.128552 | G34: =(E34-E33)*100 -> 0 | H34: =IF(AND(ISNUMBER(D34),ISNUMBER(D33)),(D34/D33-1)*100,"") -> -0.00046424106 | I34: =LN(B34/B33) -> 0.18339225 | J34: 11
A35: 45931 | B35: 37.04 | C35: 9.41 | D35: 129.2388 | E35: 0.0925 | F35: =(B35/B34-1)*100 -> 4.3086455 | G35: =(E35-E34)*100 -> -0.25 | H35: =IF(AND(ISNUMBER(D35),ISNUMBER(D34)),(D35/D34-1)*100,"") -> -0.002940207 | I35: =LN(B35/B34) -> 0.042184063 | J35: 12
... A47: 46296 | B47: 46.79 | C47: 9.04 | D47: 129.8229 | E47: 0.0875 | F47: =(B47/B46-1)*100 -> -2.9856936 | G47: =(E47-E46)*100 -> 0 | H47: =IF(AND(ISNUMBER(D47),ISNUMBER(D46)),(D47/D46-1)*100,"") -> 0.22775016 | I47: =LN(B47/B46) -> -0.030311729 | J47: 24

Sheet Summary Stats
A1: Historical findings (calculated from Data sheet)
A3: Measure | B3: Value | C3: Note
A4: First price (Jan 2023, KES) | B4: =Data!B2 -> 23.23
A5: Latest price (Oct 2026, KES) | B5: =Data!B47 -> 46.79 | C5: Oct 2026 may be provisional
A6: Cumulative change | B6: =B5/B4-1 -> 1.0142058
A7: Highest price (KES) | B7: =MAX(Data!B2:B47) -> 48.23
A8: Lowest price (KES) | B8: =MIN(Data!B2:B47) -> 16.37
A9: Mean monthly return (%) | B9: =AVERAGE(Data!F3:F47) -> 1.7926018 | C9: n = 45 returns
A10: Median monthly return (%) | B10: =MEDIAN(Data!F3:F47) -> 1.1988012
A11: Std deviation of monthly return (%) | B11: =STDEV(Data!F3:F47) -> 6.9217602 | C11: Volatility
A12: Largest monthly gain (%) | B12: =MAX(Data!F3:F47) -> 22.199256
A13: Largest monthly fall (%) | B13: =MIN(Data!F3:F47) -> -12.017354
A14: Correlation: return vs change in rate | B14: =CORREL(Data!F7:F47,Data!G7:G47) -> -0.07092173 | C14: Monthly changes, n = 41
A15: Correlation: return vs change in KES/USD | B15: =CORREL(Data!F7:F47,Data!H7:H47) -> -0.11822814 | C15: Monthly changes, n = 41
A16: Correlation: price vs interest rate (levels) | B16: =CORREL(Data!B2:B47,Data!E2:E47) -> -0.68452897 | C16: Levels trend together: not evidence of cause
A17: Correlation: price vs inflation (levels) | B17: =CORREL(Data!B2:B47,Data!C2:C47) -> -0.73759834 | C17: Same caution
A18: Correlation: price vs KES/USD (levels) | B18: =CORREL(Data!B6:B47,Data!D6:D47) -> -0.50948724 | C18: May 2023 onward
A21: Year | B21: Start price | C21: End price | D21: Change
A22: 2023 | B22: =Data!B2 -> 23.23 | C22: =Data!B13 -> 16.82 | D22: =C22/B22-1 -> -0.27593629
A23: 2024 | B23: =Data!B14 -> 17.55 | C23: =Data!B25 -> 20.36 | D23: =C23/B23-1 -> 0.16011396
A24: 2025 | B24: =Data!B26 -> 21.37 | C24: =Data!B37 -> 37.61 | D24: =C24/B24-1 -> 0.75994385
A25: 2026 (to Oct) | B25: =Data!B38 -> 38.79 | C25: =Data!B47 -> 46.79 | D25: =C25/B25-1 -> 0.20623872

Sheet Regression
A1: Regression: Return = b0 + b1 x Change in rate + b2 x Change in KES/USD
A2: Y = Data!F7:F47 (return, %). X1 = Data!G7:H47 columns G (change in rate, pp) and H (% change in KES/USD). Estimated with LINEST (same result as Excel Data Analysis > Regression).
A5: Term | B5: Coefficient | C5: Std error | D5: t-stat | E5: p-value | F5: Lower 95% | G5: Upper 95%
A6: Intercept (b0) | B6: =INDEX(LINEST(Data!$F$7:$F$47,Data!$G$7:$H$47,TRUE(),TRUE()),1,3) -> 2.1479041 | C6: =INDEX(LINEST(Data!$F$7:$F$47,Data!$G$7:$H$47,TRUE(),TRUE()),2,3) -> 1.1153617 | D6: =B6/C6 -> 1.9257467 | E6: =TDIST(ABS(D6),$B$17,2) -> 0.061642726 | F6: =B6-TINV(0.05,$B$17)*C6 -> -0.11002761 | G6: =B6+TINV(0.05,$B$17)*C6 -> 4.4058358
A7: Change in rate (b1) | B7: =INDEX(LINEST(Data!$F$7:$F$47,Data!$G$7:$H$47,TRUE(),TRUE()),1,2) -> -1.0716939 | C7: =INDEX(LINEST(Data!$F$7:$F$47,Data!$G$7:$H$47,TRUE(),TRUE()),2,2) -> 2.5934237 | D7: =B7/C7 -> -0.41323517 | E7: =TDIST(ABS(D7),$B$17,2) -> 0.68175703 | F7: =B7-TINV(0.05,$B$17)*C7 -> -6.3218058 | G7: =B7+TINV(0.05,$B$17)*C7 -> 4.178418
A8: Change in KES/USD (b2) | B8: =INDEX(LINEST(Data!$F$7:$F$47,Data!$G$7:$H$47,TRUE(),TRUE()),1,1) -> -0.39751993 | C8: =INDEX(LINEST(Data!$F$7:$F$47,Data!$G$7:$H$47,TRUE(),TRUE()),2,1) -> 0.55277401 | D8: =B8/C8 -> -0.71913643 | E8: =TDIST(ABS(D8),$B$17,2) -> 0.47645627 | F8: =B8-TINV(0.05,$B$17)*C8 -> -1.5165524 | G8: =B8+TINV(0.05,$B$17)*C8 -> 0.72151256
A10: Statistic | B10: Value
A11: R-squared | B11: =INDEX(LINEST(Data!$F$7:$F$47,Data!$G$7:$H$47,TRUE(),TRUE()),3,1) -> 0.018389028
A12: Adjusted R-squared | B12: =1-(1-B11)*(B16-1)/B17 -> -0.033274707
A13: F-statistic | B13: =INDEX(LINEST(Data!$F$7:$F$47,Data!$G$7:$H$47,TRUE(),TRUE()),4,1) -> 0.35593687
A14: F-test p-value | B14: =FDIST(B13,2,B17) -> 0.70282739
A15: Std error of regression | B15: =INDEX(LINEST(Data!$F$7:$F$47,Data!$G$7:$H$47,TRUE(),TRUE()),3,2) -> 7.1201537
A16: Observations (n) | B16: =COUNT(Data!$F$7:$F$47) -> 41
A17: Residual degrees of freedom | B17: =INDEX(LINEST(Data!$F$7:$F$47,Data!$G$7:$H$47,TRUE(),TRUE()),4,2) -> 38
A19: Interpretation
A20: b0: average monthly return (%) when rates and FX do not change.
A21: b1: change in monthly return (pp) for a 1 percentage-point rise in the interest rate, holding FX constant.
A22: b2: change in monthly return (pp) for a 1% weaker shilling, holding the rate constant.
A23: p-values above 0.05 mean the coefficient is not statistically different from zero; the F-test p-value tests all slopes together.
A24: Low R-squared and high p-values: the macro variables explain almost none of the return variation. This is correlation, not proof of causation.

Sheet Scenarios
A1: 2027 scenario assumptions and calculations
A3: Assumption | B3: Value | C3: Source / note
A4: Starting price, Oct 2026 (KES) | B4: =Data!B47 -> 46.79 | C4: Actual (Rock Data Plus)
A5: Starting interest rate | B5: =Data!E47 -> 0.0875 | C5: Actual
A6: Starting KES/USD | B6: =Data!D47 -> 129.8229 | C6: Actual
A7: Intercept b0 (% per month) | B7: =Regression!B6 -> 2.1479041 | C7: Estimated
A8: b1: rate coefficient | B8: =Regression!B7 -> -1.0716939 | C8: Estimated
A9: b2: FX coefficient | B9: =Regression!B8 -> -0.39751993 | C9: Estimated
A10: Lower 95% bound of intercept | B10: =Regression!F6 -> -0.11002761 | C10: Estimated
A11: Base: share of intercept used as drift | B11: 0.5 | C11: ASSUMPTION: intercept is not significant at 5% and reflects the 2025-26 rally
A12: Optimistic: share of intercept used as drift | B12: 1 | C12: ASSUMPTION
A13: Base drift (% per month) | B13: =B11*B7 -> 1.073952 | C13: Share x intercept
A14: Optimistic drift (% per month) | B14: =B12*B7 -> 2.1479041 | C14: Share x intercept
A15: Pessimistic drift (% per month) | B15: =B10 -> -0.11002761 | C15: Lower 95% bound of intercept
A18: BASE CASE: rate and FX held flat
A19: Month | B19: Change in rate (pp) [input] | C19: Change in KES/USD (%) [input] | D19: Interest rate | E19: KES/USD | F19: Predicted return (%) | G19: Projected price (KES)
A20: 46388 | B20: 0 | C20: 0 | D20: =$B$5+B20/100 -> 0.0875 | E20: =$B$6*(1+C20/100) -> 129.8229 | F20: =$B$13+$B$8*B20+$B$9*C20 -> 1.073952 | G20: =$B$4*(1+F20/100) -> 47.292502
A21: 46419 | B21: 0 | C21: 0 | D21: =D20+B21/100 -> 0.0875 | E21: =E20*(1+C21/100) -> 129.8229 | F21: =$B$13+$B$8*B21+$B$9*C21 -> 1.073952 | G21: =G20*(1+F21/100) -> 47.800401
A22: 46447 | B22: 0 | C22: 0 | D22: =D21+B22/100 -> 0.0875 | E22: =E21*(1+C22/100) -> 129.8229 | F22: =$B$13+$B$8*B22+$B$9*C22 -> 1.073952 | G22: =G21*(1+F22/100) -> 48.313754
A23: 46478 | B23: 0 | C23: 0 | D23: =D22+B23/100 -> 0.0875 | E23: =E22*(1+C23/100) -> 129.8229 | F23: =$B$13+$B$8*B23+$B$9*C23 -> 1.073952 | G23: =G22*(1+F23/100) -> 48.832621
A24: 46508 | B24: 0 | C24: 0 | D24: =D23+B24/100 -> 0.0875 | E24: =E23*(1+C24/100) -> 129.8229 | F24: =$B$13+$B$8*B24+$B$9*C24 -> 1.073952 | G24: =G23*(1+F24/100) -> 49.35706
A25: 46539 | B25: 0 | C25: 0 | D25: =D24+B25/100 -> 0.0875 | E25: =E24*(1+C25/100) -> 129.8229 | F25: =$B$13+$B$8*B25+$B$9*C25 -> 1.073952 | G25: =G24*(1+F25/100) -> 49.887131
A26: 46569 | B26: 0 | C26: 0 | D26: =D25+B26/100 -> 0.0875 | E26: =E25*(1+C26/100) -> 129.8229 | F26: =$B$13+$B$8*B26+$B$9*C26 -> 1.073952 | G26: =G25*(1+F26/100) -> 50.422895
A27: 46600 | B27: 0 | C27: 0 | D27: =D26+B27/100 -> 0.0875 | E27: =E26*(1+C27/100) -> 129.8229 | F27: =$B$13+$B$8*B27+$B$9*C27 -> 1.073952 | G27: =G26*(1+F27/100) -> 50.964413
A28: 46631 | B28: 0 | C28: 0 | D28: =D27+B28/100 -> 0.0875 | E28: =E27*(1+C28/100) -> 129.8229 | F28: =$B$13+$B$8*B28+$B$9*C28 -> 1.073952 | G28: =G27*(1+F28/100) -> 51.511746
A29: 46661 | B29: 0 | C29: 0 | D29: =D28+B29/100 -> 0.0875 | E29: =E28*(1+C29/100) -> 129.8229 | F29: =$B$13+$B$8*B29+$B$9*C29 -> 1.073952 | G29: =G28*(1+F29/100) -> 52.064957
A30: 46692 | B30: 0 | C30: 0 | D30: =D29+B30/100 -> 0.0875 | E30: =E29*(1+C30/100) -> 129.8229 | F30: =$B$13+$B$8*B30+$B$9*C30 -> 1.073952 | G30: =G29*(1+F30/100) -> 52.62411
A31: 46722 | B31: 0 | C31: 0 | D31: =D30+B31/100 -> 0.0875 | E31: =E30*(1+C31/100) -> 129.8229 | F31: =$B$13+$B$8*B31+$B$9*C31 -> 1.073952 | G31: =G30*(1+F31/100) -> 53.189268
A33: OPTIMISTIC CASE: rate cuts, FX flat
A34: Month | B34: Change in rate (pp) [input] | C34: Change in KES/USD (%) [input] | D34: Interest rate | E34: KES/USD | F34: Predicted return (%) | G34: Projected price (KES)
A35: 46388 | B35: 0 | C35: 0 | D35: =$B$5+B35/100 -> 0.0875 | E35: =$B$6*(1+C35/100) -> 129.8229 | F35: =$B$14+$B$8*B35+$B$9*C35 -> 2.1479041 | G35: =$B$4*(1+F35/100) -> 47.795004
A36: 46419 | B36: 0 | C36: 0 | D36: =D35+B36/100 -> 0.0875 | E36: =E35*(1+C36/100) -> 129.8229 | F36: =$B$14+$B$8*B36+$B$9*C36 -> 2.1479041 | G36: =G35*(1+F36/100) -> 48.821595
A37: 46447 | B37: -0.25 | C37: 0 | D37: =D36+B37/100 -> 0.085 | E37: =E36*(1+C37/100) -> 129.8229 | F37: =$B$14+$B$8*B37+$B$9*C37 -> 2.4158276 | G37: =G36*(1+F37/100) -> 50.001041
A38: 46478 | B38: 0 | C38: 0 | D38: =D37+B38/100 -> 0.085 | E38: =E37*(1+C38/100) -> 129.8229 | F38: =$B$14+$B$8*B38+$B$9*C38 -> 2.1479041 | G38: =G37*(1+F38/100) -> 51.075015
A39: 46508 | B39: 0 | C39: 0 | D39: =D38+B39/100 -> 0.085 | E39: =E38*(1+C39/100) -> 129.8229 | F39: =$B$14+$B$8*B39+$B$9*C39 -> 2.1479041 | G39: =G38*(1+F39/100) -> 52.172057
A40: 46539 | B40: -0.25 | C40: 0 | D40: =D39+B40/100 -> 0.0825 | E40: =E39*(1+C40/100) -> 129.8229 | F40: =$B$14+$B$8*B40+$B$9*C40 -> 2.4158276 | G40: =G39*(1+F40/100) -> 53.432444
A41: 46569 | B41: 0 | C41: 0 | D41: =D40+B41/100 -> 0.0825 | E41: =E40*(1+C41/100) -> 129.8229 | F41: =$B$14+$B$8*B41+$B$9*C41 -> 2.1479041 | G41: =G40*(1+F41/100) -> 54.580122
A42: 46600 | B42: 0 | C42: 0 | D42: =D41+B42/100 -> 0.0825 | E42: =E41*(1+C42/100) -> 129.8229 | F42: =$B$14+$B$8*B42+$B$9*C42 -> 2.1479041 | G42: =G41*(1+F42/100) -> 55.752451
A43: 46631 | B43: -0.25 | C43: 0 | D43: =D42+B43/100 -> 0.08 | E43: =E42*(1+C43/100) -> 129.8229 | F43: =$B$14+$B$8*B43+$B$9*C43 -> 2.4158276 | G43: =G42*(1+F43/100) -> 57.099334
A44: 46661 | B44: 0 | C44: 0 | D44: =D43+B44/100 -> 0.08 | E44: =E43*(1+C44/100) -> 129.8229 | F44: =$B$14+$B$8*B44+$B$9*C44 -> 2.1479041 | G44: =G43*(1+F44/100) -> 58.325773
...

Sheet Forecast Table
A1: January - December 2027: scenario projections (model-based; assumptions, not observations)
A3: Month | B3: Base: rate | C3: Base: KES/USD | D3: Base: return (%) | E3: Base: price (KES) | F3: Optimistic: rate | G3: Optimistic: KES/USD | H3: Optimistic: return (%) | I3: Optimistic: price (KES) | J3: Pessimistic: rate | K3: Pessimistic: KES/USD | L3: Pessimistic: return (%) | M3: Pessimistic: price (KES)
A4: =Scenarios!A20 -> 46388 | B4: =Scenarios!D20 -> 0.0875 | C4: =Scenarios!E20 -> 129.8229 | D4: =Scenarios!F20 -> 1.073952 | E4: =Scenarios!G20 -> 47.292502 | F4: =Scenarios!D35 -> 0.0875 | G4: =Scenarios!E35 -> 129.8229 | H4: =Scenarios!F35 -> 2.1479041 | I4: =Scenarios!G35 -> 47.795004 | J4: =Scenarios!D50 -> 0.0875 | K4: =Scenarios!E50 -> 130.47201 | L4: =Scenarios!F50 -> -0.30878757 | M4: =Scenarios!G50 -> 46.645518
A5: =Scenarios!A21 -> 46419 | B5: =Scenarios!D21 -> 0.0875 | C5: =Scenarios!E21 -> 129.8229 | D5: =Scenarios!F21 -> 1.073952 | E5: =Scenarios!G21 -> 47.800401 | F5: =Scenarios!D36 -> 0.0875 | G5: =Scenarios!E36 -> 129.8229 | H5: =Scenarios!F36 -> 2.1479041 | I5: =Scenarios!G36 -> 48.821595 | J5: =Scenarios!D51 -> 0.09 | K5: =Scenarios!E51 -> 131.12437 | L5: =Scenarios!F51 -> -0.57671105 | M5: =Scenarios!G51 -> 46.376508
A6: =Scenarios!A22 -> 46447 | B6: =Scenarios!D22 -> 0.0875 | C6: =Scenarios!E22 -> 129.8229 | D6: =Scenarios!F22 -> 1.073952 | E6: =Scenarios!G22 -> 48.313754 | F6: =Scenarios!D37 -> 0.085 | G6: =Scenarios!E37 -> 129.8229 | H6: =Scenarios!F37 -> 2.4158276 | I6: =Scenarios!G37 -> 50.001041 | J6: =Scenarios!D52 -> 0.09 | K6: =Scenarios!E52 -> 131.78 | L6: =Scenarios!F52 -> -0.30878757 | M6: =Scenarios!G52 -> 46.233304
A7: =Scenarios!A23 -> 46478 | B7: =Scenarios!D23 -> 0.0875 | C7: =Scenarios!E23 -> 129.8229 | D7: =Scenarios!F23 -> 1.073952 | E7: =Scenarios!G23 -> 48.832621 | F7: =Scenarios!D38 -> 0.085 | G7: =Scenarios!E38 -> 129.8229 | H7: =Scenarios!F38 -> 2.1479041 | I7: =Scenarios!G38 -> 51.075015 | J7: =Scenarios!D53 -> 0.09 | K7: =Scenarios!E53 -> 132.4389 | L7: =Scenarios!F53 -> -0.30878757 | M7: =Scenarios!G53 -> 46.090541
A8: =Scenarios!A24 -> 46508 | B8: =Scenarios!D24 -> 0.0875 | C8: =Scenarios!E24 -> 129.8229 | D8: =Scenarios!F24 -> 1.073952 | E8: =Scenarios!G24 -> 49.35706 | F8: =Scenarios!D39 -> 0.085 | G8: =Scenarios!E39 -> 129.8229 | H8: =Scenarios!F39 -> 2.1479041 | I8: =Scenarios!G39 -> 52.172057 | J8: =Scenarios!D54 -> 0.0925 | K8: =Scenarios!E54 -> 133.10109 | L8: =Scenarios!F54 -> -0.57671105 | M8: =Scenarios!G54 -> 45.824732
A9: =Scenarios!A25 -> 46539 | B9: =Scenarios!D25 -> 0.0875 | C9: =Scenarios!E25 -> 129.8229 | D9: =Scenarios!F25 -> 1.073952 | E9: =Scenarios!G25 -> 49.887131 | F9: =Scenarios!D40 -> 0.0825 | G9: =Scenarios!E40 -> 129.8229 | H9: =Scenarios!F40 -> 2.4158276 | I9: =Scenarios!G40 -> 53.432444 | J9: =Scenarios!D55 -> 0.0925 | K9: =Scenarios!E55 -> 133.7666 | L9: =Scenarios!F55 -> -0.30878757 | M9: =Scenarios!G55 -> 45.683231
A10: =Scenarios!A26 -> 46569 | B10: =Scenarios!D26 -> 0.0875 | C10: =Scenarios!E26 -> 129.8229 | D10: =Scenarios!F26 -> 1.073952 | E10: =Scenarios!G26 -> 50.422895 | F10: =Scenarios!D41 -> 0.0825 | G10: =Scenarios!E41 -> 129.8229 | H10: =Scenarios!F41 -> 2.1479041 | I10: =Scenarios!G41 -> 54.580122 | J10: =Scenarios!D56 -> 0.0925 | K10: =Scenarios!E56 -> 134.43543 | L10: =Scenarios!F56 -> -0.30878757 | M10: =Scenarios!G56 -> 45.542166
A11: =Scenarios!A27 -> 46600 | B11: =Scenarios!D27 -> 0.0875 | C11: =Scenarios!E27 -> 129.8229 | D11: =Scenarios!F27 -> 1.073952 | E11: =Scenarios!G27 -> 50.964413 | F11: =Scenarios!D42 -> 0.0825 | G11: =Scenarios!E42 -> 129.8229 | H11: =Scenarios!F42 -> 2.1479041 | I11: =Scenarios!G42 -> 55.752451 | J11: =Scenarios!D57 -> 0.0925 | K11: =Scenarios!E57 -> 135.10761 | L11: =Scenarios!F57 -> -0.30878757 | M11: =Scenarios!G57 -> 45.401538
A12: =Scenarios!A28 -> 46631 | B12: =Scenarios!D28 -> 0.0875 | C12: =Scenarios!E28 -> 129.8229 | D12: =Scenarios!F28 -> 1.073952 | E12: =Scenarios!G28 -> 51.511746 | F12: =Scenarios!D43 -> 0.08 | G12: =Scenarios!E43 -> 129.8229 | H12: =Scenarios!F43 -> 2.4158276 | I12: =Scenarios!G43 -> 57.099334 | J12: =Scenarios!D58 -> 0.0925 | K12: =Scenarios!E58 -> 135.78314 | L12: =Scenarios!F58 -> -0.30878757 | M12: =Scenarios!G58 -> 45.261344
A13: =Scenarios!A29 -> 46661 | B13: =Scenarios!D29 -> 0.0875 | C13: =Scenarios!E29 -> 129.8229 | D13: =Scenarios!F29 -> 1.073952 | E13: =Scenarios!G29 -> 52.064957 | F13: =Scenarios!D44 -> 0.08 | G13: =Scenarios!E44 -> 129.8229 | H13: =Scenarios!F44 -> 2.1479041 | I13: =Scenarios!G44 -> 58.325773 | J13: =Scenarios!D59 -> 0.0925 | K13: =Scenarios!E59 -> 136.46206 | L13: =Scenarios!F59 -> -0.30878757 | M13: =Scenarios!G59 -> 45.121582
A14: =Scenarios!A30 -> 46692 | B14: =Scenarios!D30 -> 0.0875 | C14: =Scenarios!E30 -> 129.8229 | D14: =Scenarios!F30 -> 1.073952 | E14: =Scenarios!G30 -> 52.62411 | F14: =Scenarios!D45 -> 0.08 | G14: =Scenarios!E45 -> 129.8229 | H14: =Scenarios!F45 -> 2.1479041 | I14: =Scenarios!G45 -> 59.578554 | J14: =Scenarios!D60 -> 0.0925 | K14: =Scenarios!E60 -> 137.14437 | L14: =Scenarios!F60 -> -0.30878757 | M14: =Scenarios!G60 -> 44.982252
A15: =Scenarios!A31 -> 46722 | B15: =Scenarios!D31 -> 0.0875 | C15: =Scenarios!E31 -> 129.8229 | D15: =Scenarios!F31 -> 1.073952 | E15: =Scenarios!G31 -> 53.189268 | F15: =Scenarios!D46 -> 0.08 | G15: =Scenarios!E46 -> 129.8229 | H15: =Scenarios!F46 -> 2.1479041 | I15: =Scenarios!G46 -> 60.858245 | J15: =Scenarios!D61 -> 0.0925 | K15: =Scenarios!E61 -> 137.83009 | L15: =Scenarios!F61 -> -0.30878757 | M15: =Scenarios!G61 -> 44.843353
A17: Dec-27 vs Oct-26 | E17: =E15/Data!B47-1 -> 0.13676571 | I17: =I15/Data!B47-1 -> 0.30066776 | M17: =M15/Data!B47-1 -> -0.041603918

Sheet Cross-check
A1: Price-only cross-check methods (KES): use only the share price series, no macro variables
A3: Mean log monthly return | B3: =AVERAGE(Data!I3:I47) -> 0.015560555
A4: 24-month trend slope (KES/month) | B4: =SLOPE(Data!B24:B47,Data!J24:J47) -> 1.3972087
A5: 24-month trend intercept | B5: =INTERCEPT(Data!B24:B47,Data!J24:J47) -> 16.879891
A7: Month | B7: Naive (no change) | C7: Random walk + drift | D7: Damped Holt trend | E7: ARIMA(1,1,0) + drift | F7: Linear trend (last 24 months)
A8: 46388 | B8: =Data!$B$47 -> 46.79 | C8: =Data!$B$47*EXP($B$3*1) -> 47.523772 | D8: 47.3 | E8: 47.11 | F8: =$B$5+$B$4*(25) -> 51.810109
A9: 46419 | B9: =Data!$B$47 -> 46.79 | C9: =Data!$B$47*EXP($B$3*2) -> 48.269052 | D9: 47.71 | E9: 47.75 | F9: =$B$5+$B$4*(26) -> 53.207317
A10: 46447 | B10: =Data!$B$47 -> 46.79 | C10: =Data!$B$47*EXP($B$3*3) -> 49.02602 | D10: 48.09 | E10: 48.46 | F10: =$B$5+$B$4*(27) -> 54.604526
A11: 46478 | B11: =Data!$B$47 -> 46.79 | C11: =Data!$B$47*EXP($B$3*4) -> 49.794858 | D11: 48.44 | E11: 49.2 | F11: =$B$5+$B$4*(28) -> 56.001735
A12: 46508 | B12: =Data!$B$47 -> 46.79 | C12: =Data!$B$47*EXP($B$3*5) -> 50.575753 | D12: 48.77 | E12: 49.94 | F12: =$B$5+$B$4*(29) -> 57.398943
A13: 46539 | B13: =Data!$B$47 -> 46.79 | C13: =Data!$B$47*EXP($B$3*6) -> 51.368895 | D13: 49.08 | E13: 50.7 | F13: =$B$5+$B$4*(30) -> 58.796152
A14: 46569 | B14: =Data!$B$47 -> 46.79 | C14: =Data!$B$47*EXP($B$3*7) -> 52.174475 | D14: 49.36 | E14: 51.47 | F14: =$B$5+$B$4*(31) -> 60.193361
A15: 46600 | B15: =Data!$B$47 -> 46.79 | C15: =Data!$B$47*EXP($B$3*8) -> 52.992688 | D15: 49.62 | E15: 52.26 | F15: =$B$5+$B$4*(32) -> 61.59057
A16: 46631 | B16: =Data!$B$47 -> 46.79 | C16: =Data!$B$47*EXP($B$3*9) -> 53.823733 | D16: 49.86 | E16: 53.05 | F16: =$B$5+$B$4*(33) -> 62.987778
A17: 46661 | B17: =Data!$B$47 -> 46.79 | C17: =Data!$B$47*EXP($B$3*10) -> 54.66781 | D17: 50.09 | E17: 53.86 | F17: =$B$5+$B$4*(34) -> 64.384987
A18: 46692 | B18: =Data!$B$47 -> 46.79 | C18: =Data!$B$47*EXP($B$3*11) -> 55.525124 | D18: 50.29 | E18: 54.68 | F18: =$B$5+$B$4*(35) -> 65.782196
A19: 46722 | B19: =Data!$B$47 -> 46.79 | C19: =Data!$B$47*EXP($B$3*12) -> 56.395883 | D19: 50.49 | E19: 55.51 | F19: =$B$5+$B$4*(36) -> 67.179404
A21: Convention: every method starts from the Oct 2026 price and treats Jan 2027 as the first forecast step (Nov-Dec 2026 skipped), the same as the Scenarios sheet. Damped Holt and ARIMA(1,1,0) values are hard-coded from Python (statsmodels) fitted to the same price series; other columns are live formulas. Linear trend uses t = 1..24 for Nov-24 to Oct-26, so Jan-27 is t = 25.

Sheet Chart Data
A1: Month | B1: Actual | C1: Base | D1: Optimistic | E1: Pessimistic
A2: =Data!A2 -> 44927 | B2: =Data!B2 -> 23.23
A3: =Data!A3 -> 44958 | B3: =Data!B3 -> 22.47
A4: =Data!A4 -> 44986 | B4: =Data!B4 -> 20.63
A5: =Data!A5 -> 45017 | B5: =Data!B5 -> 21.19
A6: =Data!A6 -> 45047 | B6: =Data!B6 -> 20.84
A7: =Data!A7 -> 45078 | B7: =Data!B7 -> 20.65
A8: =Data!A8 -> 45108 | B8: =Data!B8 -> 19.42
A9: =Data!A9 -> 45139 | B9: =Data!B9 -> 19.48
A10: =Data!A10 -> 45170 | B10: =Data!B10 -> 18.33
A11: =Data!A11 -> 45200 | B11: =Data!B11 -> 17.4
A12: =Data!A12 -> 45231 | B12: =Data!B12 -> 16.37
A13: =Data!A13 -> 45261 | B13: =Data!B13 -> 16.82
... A46: =Data!A46 -> 46266 | B46: =Data!B46 -> 48.23
A47: =Data!A47 -> 46296 | B47: =Data!B47 -> 46.79 | C47: =Data!B47 -> 46.79 | D47: =Data!B47 -> 46.79 | E47: =Data!B47 -> 46.79
A48: =Scenarios!A20 -> 46388 | C48: =Scenarios!G20 -> 47.292502 | D48: =Scenarios!G35 -> 47.795004 | E48: =Scenarios!G50 -> 46.645518
A49: =Scenarios!A21 -> 46419 | C49: =Scenarios!G21 -> 47.800401 | D49: =Scenarios!G36 -> 48.821595 | E49: =Scenarios!G51 -> 46.376508
A50: =Scenarios!A22 -> 46447 | C50: =Scenarios!G22 -> 48.313754 | D50: =Scenarios!G37 -> 50.001041 | E50: =Scenarios!G52 -> 46.233304
A51: =Scenarios!A23 -> 46478 | C51: =Scenarios!G23 -> 48.832621 | D51: =Scenarios!G38 -> 51.075015 | E51: =Scenarios!G53 -> 46.090541
A52: =Scenarios!A24 -> 46508 | C52: =Scenarios!G24 -> 49.35706 | D52: =Scenarios!G39 -> 52.172057 | E52: =Scenarios!G54 -> 45.824732
A53: =Scenarios!A25 -> 46539 | C53: =Scenarios!G25 -> 49.887131 | D53: =Scenarios!G40 -> 53.432444 | E53: =Scenarios!G55 -> 45.683231
A54: =Scenarios!A26 -> 46569 | C54: =Scenarios!G26 -> 50.422895 | D54: =Scenarios!G41 -> 54.580122 | E54: =Scenarios!G56 -> 45.542166
A55: =Scenarios!A27 -> 46600 | C55: =Scenarios!G27 -> 50.964413 | D55: =Scenarios!G42 -> 55.752451 | E55: =Scenarios!G57 -> 45.401538
A56: =Scenarios!A28 -> 46631 | C56: =Scenarios!G28 -> 51.511746 | D56: =Scenarios!G43 -> 57.099334 | E56: =Scenarios!G58 -> 45.261344
A57: =Scenarios!A29 -> 46661 | C57: =Scenarios!G29 -> 52.064957 | D57: =Scenarios!G44 -> 58.325773 | E57: =Scenarios!G59 -> 45.121582
A58: =Scenarios!A30 -> 46692 | C58: =Scenarios!G30 -> 52.62411 | D58: =Scenarios!G45 -> 59.578554 | E58: =Scenarios!G60 -> 44.982252
A59: =Scenarios!A31 -> 46722 | C59: =Scenarios!G31 -> 53.189268 | D59: =Scenarios!G46 -> 60.858245 | E59: =Scenarios!G61 -> 44.843353

Sheet Chart

Sheet Qualitative Factors
A1: Qualitative factors from the draft (Rock Data Plus context) and how this workbook treats them
A3: Factor | B3: Expected effect on TOTL (hypothesis, not proven) | C3: Data in this workbook? | D3: What the data show | E3: Treatment in 2027 scenarios
A4: Foreign exchange (KES/USD) | B4: Petroleum is priced in USD; a weaker shilling can raise import costs and squeeze margins, depending on pricing mechanisms and hedging. | C4: Yes | D4: ="Correlation of return with change in FX: "&TEXT('Summary Stats'!B15,"0.00")&"; coefficient p-value "&TEXT(Regression!E8,"0.00") -> Correlation of return with change in FX: -0.12; coefficient p-value 0.48 | E4: Modelled: FX path assumption x b2
A5: Interest rate | B5: Higher rates raise borrowing costs and make bonds more attractive vs shares, lowering valuations. | C5: Yes | D5: ="Correlation of return with change in rate: "&TEXT('Summary Stats'!B14,"0.00")&"; coefficient p-value "&TEXT(Regression!E7,"0.00") -> Correlation of return with change in rate: -0.07; coefficient p-value 0.68 | E5: Modelled: rate path assumption x b1
A6: Consumer price inflation | B6: Raises transport, distribution and labour costs and can reduce demand; effect depends on regulated vs market fuel prices. | C6: Yes (not in main model) | D6: ="Price vs inflation (levels) correlation: "&TEXT('Summary Stats'!B17,"0.00")&"; inflation and rates move together, so it is left out to avoid double counting" -> Price vs inflation (levels) correlation: -0.74; inflation and rates move together, so it is left out to avoid double counting | E6: Not modelled separately; captured partly via the rate path
A7: GDP growth | B7: Stronger growth supports fuel demand and volumes; slower growth constrains demand. | C7: No | D7: No GDP series supplied | E7: Qualitative only; add KNBS GDP data to test
A8: International oil prices | B8: Affect procurement cost, domestic fuel pricing and expectations. | C8: No | D8: No oil-price series supplied | E8: Qualitative only; add Brent data to test
A9: Company-specific factors (earnings, dividends, competition, margins) | B9: Likely drivers of the 2025 rally, since rates and FX barely moved in Aug-Nov 2025. | C9: No | D9: No financial statements supplied | E9: Not modelled; needed for a fundamental valuation (P/E, DDM)
A11: These effects are plausible channels, not confirmed relationships. Correlation does not prove causation.
